Workbook

Sheet Read Me
A1: Slang — Commercial Model v1.0
A3: What this is | B3: A driver-based model for Slang as an Arabic-L1 English pronunciation product, GCC-first. It replaces the model audited on 2026-09-12, which reported revenue that did not follow from its own inputs (the paid-conversion column was never applied) and overstated 2027 by roughly 20x.
A4: The finding it encodes | B4: Inference is paid on EVERY monthly active. Revenue is earned on the 3-8% who convert. At the old architecture's cost-to-serve, gross profit was negative in all three forecast years. The free tier — not customer acquisition — was the thing breaking the business.
A5: How the fix works | B5: 'Cost to Serve' models the ADR-0001 architecture: self-hosted wav2vec2 GOP replaces per-call LLM assessment. The same investment that creates the technical moat is what makes a free tier survivable. That is the central claim of this model and it is testable in cell terms.
A7: COLOUR CONVENTION
A8: Blue text | B8: A hardcoded input. Change these.
A9: Black text | B9: A formula. Do not overwrite — it will break the model.
A10: Green text | B10: A link to another sheet in this workbook.
A11: Yellow fill | B11: A KEY assumption that materially moves the answer, or an estimate that still needs validating. Read the note column before trusting it.
A13: ORDER OF USE
A14: 1. Assumptions | B14: Set market size, funnel, retention and cost drivers. Everything downstream reads from here.
A15: 2. Price Elasticity | B15: Derives the revenue-maximising price and the affordability ceiling per market from a constant-elasticity demand curve. Set the elasticity here.
A16: 3. Cost to Serve | B16: Builds cost per session bottom-up for the current and target architectures.
A17: 4. Models A / B / C | B17: Three business models, each a full P&L on the same drivers.
A18: 5. Comparison | B18: Side by side, with the recommendation and the kill criteria.
A19: 6. Sensitivity | B19: What breaks the recommended model, and at what value.
A20: 7. Sources | B20: Every external number, with where it came from. Nothing in this workbook is asserted without a source or an explicit ESTIMATE flag.
A22: RULE | B22: If you add a number to a slide from this workbook, cite the cell. If a cell is yellow, say it is an estimate. That discipline is what the 2026-09-12 audit found missing, and it is cheaper than being caught.

Sheet Assumptions
A1: Assumptions — every driver in the model
A3: Driver | B3: Value | C3: Unit | D3: Source / note
A4: MARKET SIZING (top-down)
A5: Global digital English learning market, 2026 | B5: 15980000000 | C5: USD | D5: Mordor Intelligence, Digital English Language Learning Market. 2026 figure; $31.62bn by 2031, 14.62% CAGR.
A6: Middle East e-learning market, 2025 | B6: 16169000000 | C6: USD | D6: IMARC, Middle East E-Learning Market. $28.28bn by 2034, 6.41% CAGR.
A7: MENA share of digital English learning | B7: 0.04 | C7: % | D7: ESTIMATE — validate. Mordor groups MEA with South America and reports only 'double-digit growth'. Bottom-up validation required before this number goes on a slide.
A8: TAM — MENA digital English learning | B8: =B5*B7 -> 639200000 | C8: USD | D8: Top-down. Cross-check against a bottom-up seat count before use.
A9: Pronunciation/speaking share of that spend | B9: 0.18 | C9: % | D9: ESTIMATE — validate. Speaking-focused tools are a minority of English-learning spend; ELSA is the reference comparable.
A10: SAM — MENA speaking-practice segment | B10: =B8*B9 -> 115056000 | C10: USD
A11: Realistic 3-year share of SAM | B11: 0.005 | C11: % | D11: ESTIMATE — validate. 0.5% of a $115m segment. Deliberately small: this is a solo-founder product with no distribution yet.
A12: SOM — 3-year revenue opportunity | B12: =B10*B11 -> 575280 | C12: USD
A14: FUNNEL
A15: Year 1 monthly active users (MAU), exit | B15: 2500 | C15: users | D15: Planning input. Set by what acquisition you can actually run, not by TAM.
A16: Year 2 MAU, exit | B16: 15000 | C16: users | D16: Planning input.
A17: Year 3 MAU, exit | B17: 55000 | C17: users | D17: Planning input.
A18: Download-to-trial, 30 days | B18: 0.065 | C18: % | D18: RevenueCat, State of Subscription Apps 2026 — Education: 6.5% median D30 download-to-trial.
A19: Trial-to-paid conversion | B19: 0.45 | C19: % | D19: ESTIMATE — validate. Not broken out for Education in the RevenueCat report. 40-50% is the common range for a 7-day trial with a payment method on file.
A20: Blended MAU-to-paid conversion | B20: =B18*B19 -> 0.02925 | C20: % | D20: This is the number the old model printed in a column and then never used.
A21: Annual plan share of paid base | B21: 0.6 | C21: % | D21: RevenueCat 2026: education is among the categories favouring annual (59-66%).
A22: Annual plan discount vs 12x monthly | B22: 0.4 | C22: % | D22: Market convention. ELSA annual is ~39% below its monthly rate ($13.33 vs $21.99).
A23: Monthly churn, paid | B23: 0.055 | C23: % | D23: ESTIMATE — validate. Implies ~18 month average life. Language apps churn hard after the first plateau.
A24: Average paid customer lifetime | B24: =IFERROR(1/B23,0) -> 18.181818 | C24: months
A26: USAGE INTENSITY (drives cost)
A27: Scored recordings per free MAU per month | B27: 12 | C27: sessions | D27: Free tier is metered at 5/week; assumes most free users do not hit the cap.
A28: Scored recordings per paid MAU per month | B28: 45 | C28: sessions | D28: Engaged learners practise most days.
A29: Companion/scenario turns per paid MAU per month | B29: 40 | C29: turns
A30: Companion/scenario turns per free MAU per month | B30: 8 | C30: turns
A31: Average utterance length | B31: 5 | C31: seconds | D31: Sentence-level practice items.
A33: MARKET MIX (drives realised price)
A34: GCC share of user base | B34: 0.45 | C34: % | D34: GCC is PPP Tier 1 — full US pricing. This is where the revenue is.
A35: Egypt / Levant / Maghreb share | B35: 0.55 | C35: % | D35: PPP Tier 2-3. Far larger population, roughly half the price point.
A36: Mix check (must equal 100%) | B36: =B34+B35 -> 1 | C36: %
A38: OPERATING COSTS
A39: Payment processing + store fee | B39: 0.15 | C39: % | D39: Apple/Google take 15% under the small-business programme; card rails are lower. Blended.
A40: Hosting + platform, monthly | B40: 120 | C40: USD/mo | D40: Vercel Pro plus object storage.
A41: GPU inference node, monthly | B41: 520 | C41: USD/mo | D41: ESTIMATE — validate. One always-on L4-class instance at roughly $0.70/hr. Serverless GPU until utilisation justifies it.
A42: Blended CAC | B42: 12 | C42: USD | D42: ESTIMATE — validate. Content/SEO/community led. Paid acquisition in MENA runs higher; this assumes organic dominates.
A43: Founder + contractor cost, monthly | B43: 0 | C43: USD/mo | D43: Zero while founder-led. Set this to a real salary before showing anyone a margin.

Sheet Price Elasticity
A1: Price: the floor, the ceiling, and what actually binds
A3: METHOD. A constant-elasticity demand curve is used to model volume response, but it is NOT used to pick the price — and saying why matters. With elasticity e > 1, modelled revenue rises monotonically as price falls, so the curve has no interior optimum and would recommend a price of zero. Constant elasticity is only valid locally. The price is therefore set by two real constraints: an AFFORDABILITY CEILING (what the market will bear) and an ACQUISITION FLOOR (the price below which a subscriber never repays what it cost to acquire them). The recommendation sits between them — and this sheet's most important output is what happens when it cannot.
A8: COMPETITIVE PRICE BAND (verified, Sep 2026)
A9: Product | B9: Monthly | C9: Annual | D9: Effective $/mo | E9: Free tier | F9: Positioning | G9: Note
A10: Duolingo Super | B10: 16.99 | C10: 119.99 | D10: =C10/12 -> 9.9991667 | E10: Yes | F10: Mass market, breadth | G10: Lite $35.99/yr. Family $143.99/yr. Not a speaking product.
A11: ELSA Speak Premium | B11: 21.99 | C11: 159.99 | D11: =C11/12 -> 13.3325 | E11: Yes | F11: Speaking specialist | G11: The true comparable. Team tier $18.20/user/mo.
A12: Education category median | B12: 9.99 | D12: =B12 -> 9.99 | E12: — | F12: Benchmark | G12: RevenueCat State of Subscription Apps 2026, median monthly price.
A14: PPP TIERS — the counter-intuitive result
A15: Multipliers are World Bank PPP indices adjusted by observed app A/B results (pricepush.app, 2026). The GCC sits in Tier 1 and pays full US pricing. 'MENA' is not a discount market — Egypt and the Maghreb are, the Gulf is not. Pricing one number for the whole region leaves money on the table in Riyadh and prices Cairo out entirely.
A18: Market | B18: PPP tier | C18: Multiplier | D18: At anchor | E18: At recommended | F18: Share of base | G18: Note
A19: Saudi Arabia, UAE, Qatar, Kuwait | B19: Tier 1 | C19: 1 | D19: =$B$12*C19 -> 9.99 | E19: =$B$53*C19 -> 9.99 | F19: =Assumptions!B34 -> 0.45 | G19: Full US pricing. Highest ARPU, smallest population.
A20: Jordan, Lebanon | B20: Tier 2 | C20: 0.7 | D20: =$B$12*C20 -> 6.993 | E20: =$B$53*C20 -> 6.993 | F20: 0.1 | G20: Applied within the non-GCC share.
A21: Egypt, Morocco, Tunisia | B21: Tier 3 | C21: 0.5 | D21: =$B$12*C21 -> 4.995 | E21: =$B$53*C21 -> 4.995 | F21: 0.45 | G21: Largest addressable population, half the price point.
A22: Blended multiplier | C22: =SUMPRODUCT(C19:C21,F19:F21)/SUM(F19:F21) -> 0.745 | G22: Turns a headline price into realised ARPU. Referenced by all three business models.
A24: DEMAND AND ACQUISITION INPUTS
A25: Reference price (anchor) | B25: =B12 -> 9.99 | C25: USD/mo | G25: Education-category median.
A26: Conversion at reference price | B26: =Assumptions!B20 -> 0.02925 | C26: % | G26: Blended MAU-to-paid from Assumptions.
A27: Price elasticity of demand (e) | B27: 1.4 | C27: — | G27: KEY. e>1 = elastic. Only valid near the anchor — do not read the curve far from $9.99.
A28: Maximum plausible conversion | B28: 0.25 | C28: % | G28: Caps the curve. No consumer subscription app converts a quarter of its monthly actives.
A29: Affordability ceiling, GCC | B29: 14 | C29: USD/mo | G29: ESTIMATE — validate with Van Westendorp. Set below ELSA's $13.33 effective annual rate so Slang is the value choice.
A30: Target LTV / CAC | B30: 3 | C30: x | G30: Standard venture threshold for a self-funding subscription business.
A32: PRICE RESPONSE — per monthly active user, per year
A33: Headline price $/mo | B33: Modelled conversion | C33: Realised ARPU per paid $/yr | D33: Contribution per MAU $/yr | E33: CAC per paid sub | F33: LTV / CAC | G33: Read
A34: 3.99 | B34: =MIN($B$28,$B$26*POWER(A34/$B$25,-$B$27)) -> 0.1057196 | C34: =A34*12*$C$22*(1-Assumptions!$B$21*Assumptions!$B$22)*(1-Assumptions!$B$39) -> 23.043208 | D34: =B34*(C34-'Cost to Serve'!$B$40)-(1-B34)*'Cost to Serve'!$B$38 -> 2.2738126 | E34: =IFERROR(Assumptions!$B$42/B34,0) -> 113.50781 | F34: =IFERROR((C34/12*Assumptions!$B$24)/E34,0) -> 0.30759074 | G34: =IF(F34>=$B$30,"funds its own growth","CAC not repaid") -> CAC not repaid
A35: 4.99 | B35: =MIN($B$28,$B$26*POWER(A35/$B$25,-$B$27)) -> 0.077299519 | C35: =A35*12*$C$22*(1-Assumptions!$B$21*Assumptions!$B$22)*(1-Assumptions!$B$39) -> 28.818448 | D35: =B35*(C35-'Cost to Serve'!$B$40)-(1-B35)*'Cost to Serve'!$B$38 -> 2.0769706 | E35: =IFERROR(Assumptions!$B$42/B35,0) -> 155.24029 | F35: =IFERROR((C35/12*Assumptions!$B$24)/E35,0) -> 0.28126921 | G35: =IF(F35>=$B$30,"funds its own growth","CAC not repaid") -> CAC not repaid
A36: 5.99 | B36: =MIN($B$28,$B$26*POWER(A36/$B$25,-$B$27)) -> 0.059857697 | C36: =A36*12*$C$22*(1-Assumptions!$B$21*Assumptions!$B$22)*(1-Assumptions!$B$39) -> 34.593688 | D36: =B36*(C36-'Cost to Serve'!$B$40)-(1-B36)*'Cost to Serve'!$B$38 -> 1.9271511 | E36: =IFERROR(Assumptions!$B$42/B36,0) -> 200.47547 | F36: =IFERROR((C36/12*Assumptions!$B$24)/E36,0) -> 0.26145183 | G36: =IF(F36>=$B$30,"funds its own growth","CAC not repaid") -> CAC not repaid
A37: 6.99 | B37: =MIN($B$28,$B$26*POWER(A37/$B$25,-$B$27)) -> 0.048222476 | C37: =A37*12*$C$22*(1-Assumptions!$B$21*Assumptions!$B$22)*(1-Assumptions!$B$39) -> 40.368928 | D37: =B37*(C37-'Cost to Serve'!$B$40)-(1-B37)*'Cost to Serve'!$B$38 -> 1.8079014 | E37: =IFERROR(Assumptions!$B$42/B37,0) -> 248.84662 | F37: =IFERROR((C37/12*Assumptions!$B$24)/E37,0) -> 0.24579415 | G37: =IF(F37>=$B$30,"funds its own growth","CAC not repaid") -> CAC not repaid
A38: 7.99 | B38: =MIN($B$28,$B$26*POWER(A38/$B$25,-$B$27)) -> 0.039990061 | C38: =A38*12*$C$22*(1-Assumptions!$B$21*Assumptions!$B$22)*(1-Assumptions!$B$39) -> 46.144168 | D38: =B38*(C38-'Cost to Serve'!$B$40)-(1-B38)*'Cost to Serve'!$B$38 -> 1.7098871 | E38: =IFERROR(Assumptions!$B$42/B38,0) -> 300.07456 | F38: =IFERROR((C38/12*Assumptions!$B$24)/E38,0) -> 0.23299344 | G38: =IF(F38>=$B$30,"funds its own growth","CAC not repaid") -> CAC not repaid
A39: 8.99 | B39: =MIN($B$28,$B$26*POWER(A39/$B$25,-$B$27)) -> 0.033904238 | C39: =A39*12*$C$22*(1-Assumptions!$B$21*Assumptions!$B$22)*(1-Assumptions!$B$39) -> 51.919408 | D39: =B39*(C39-'Cost to Serve'!$B$40)-(1-B39)*'Cost to Serve'!$B$38 -> 1.6273562 | E39: =IFERROR(Assumptions!$B$42/B39,0) -> 353.93806 | F39: =IFERROR((C39/12*Assumptions!$B$24)/E39,0) -> 0.22225858 | G39: =IF(F39>=$B$30,"funds its own growth","CAC not repaid") -> CAC not repaid
A40: 9.99 | B40: =MIN($B$28,$B$26*POWER(A40/$B$25,-$B$27)) -> 0.02925 | C40: =A40*12*$C$22*(1-Assumptions!$B$21*Assumptions!$B$22)*(1-Assumptions!$B$39) -> 57.694648 | D40: =B40*(C40-'Cost to Serve'!$B$40)-(1-B40)*'Cost to Serve'!$B$38 -> 1.5565404 | E40: =IFERROR(Assumptions!$B$42/B40,0) -> 410.25641 | F40: =IFERROR((C40/12*Assumptions!$B$24)/E40,0) -> 0.21307682 | G40: =IF(F40>=$B$30,"funds its own growth","CAC not repaid") -> CAC not repaid
A41: 11.99 | B41: =MIN($B$28,$B$26*POWER(A41/$B$25,-$B$27)) -> 0.022655346 | C41: =A41*12*$C$22*(1-Assumptions!$B$21*Assumptions!$B$22)*(1-Assumptions!$B$39) -> 69.245128 | D41: =B41*(C41-'Cost to Serve'!$B$40)-(1-B41)*'Cost to Serve'!$B$38 -> 1.4404417 | E41: =IFERROR(Assumptions!$B$42/B41,0) -> 529.67631 | F41: =IFERROR((C41/12*Assumptions!$B$24)/E41,0) -> 0.19807731 | G41: =IF(F41>=$B$30,"funds its own growth","CAC not repaid") -> CAC not repaid
A42: 13.99 | B42: =MIN($B$28,$B$26*POWER(A42/$B$25,-$B$27)) -> 0.018254618 | C42: =A42*12*$C$22*(1-Assumptions!$B$21*Assumptions!$B$22)*(1-Assumptions!$B$39) -> 80.795608 | D42: =B42*(C42-'Cost to Serve'!$B$40)-(1-B42)*'Cost to Serve'!$B$38 -> 1.3483624 | E42: =IFERROR(Assumptions!$B$42/B42,0) -> 657.3679 | F42: =IFERROR((C42/12*Assumptions!$B$24)/E42,0) -> 0.18622386 | G42: =IF(F42>=$B$30,"funds its own growth","CAC not repaid") -> CAC not repaid
A43: 15.99 | B43: =MIN($B$28,$B$26*POWER(A43/$B$25,-$B$27)) -> 0.015140134 | C43: =A43*12*$C$22*(1-Assumptions!$B$21*Assumptions!$B$22)*(1-Assumptions!$B$39) -> 92.346088 | D43: =B43*(C43-'Cost to Serve'!$B$40)-(1-B43)*'Cost to Serve'!$B$38 -> 1.2728754 | E43: =IFERROR(Assumptions!$B$42/B43,0) -> 792.59539 | F43: =IFERROR((C43/12*Assumptions!$B$24)/E43,0) -> 0.17653183 | G43: =IF(F43>=$B$30,"funds its own growth","CAC not repaid") -> CAC not repaid
A44: 17.99 | B44: =MIN($B$28,$B$26*POWER(A44/$B$25,-$B$27)) -> 0.012837307 | C44: =A44*12*$C$22*(1-Assumptions!$B$21*Assumptions!$B$22)*(1-Assumptions!$B$39) -> 103.89657 | D44: =B44*(C44-'Cost to Serve'!$B$40)-(1-B44)*'Cost to Serve'!$B$38 -> 1.2094373 | E44: =IFERROR(Assumptions!$B$42/B44,0) -> 934.7755 | F44: =IFERROR((C44/12*Assumptions!$B$24)/E44,0) -> 0.16840305 | G44: =IF(F44>=$B$30,"funds its own growth","CAC not repaid") -> CAC not repaid
A45: 19.99 | B45: =MIN($B$28,$B$26*POWER(A45/$B$25,-$B$27)) -> 0.011075916 | C45: =A45*12*$C$22*(1-Assumptions!$B$21*Assumptions!$B$22)*(1-Assumptions!$B$39) -> 115.44705 | D45: =B45*(C45-'Cost to Serve'!$B$40)-(1-B45)*'Cost to Serve'!$B$38 -> 1.1550874 | E45: =IFERROR(Assumptions!$B$42/B45,0) -> 1083.4319 | F45: =IFERROR((C45/12*Assumptions!$B$24)/E45,0) -> 0.16144972 | G45: =IF(F45>=$B$30,"funds its own growth","CAC not repaid") -> CAC not repaid
A46: 24.99 | B46: =MIN($B$28,$B$26*POWER(A46/$B$25,-$B$27)) -> 0.0081029805 | C46: =A46*12*$C$22*(1-Assumptions!$B$21*Assumptions!$B$22)*(1-Assumptions!$B$39) -> 144.32325 | D46: =B46*(C46-'Cost to Serve'!$B$40)-(1-B46)*'Cost to Serve'!$B$38 -> 1.0470701 | E46: =IFERROR(Assumptions!$B$42/B46,0) -> 1480.9365 | F46: =IFERROR((C46/12*Assumptions!$B$24)/E46,0) -> 0.14765763 | G46: =IF(F46>=$B$30,"funds its own growth","CAC not repaid") -> CAC not repaid
A48: WHAT BINDS
A49: Affordability ceiling (GCC) | B49: =B29 -> 14 | C49: USD/mo | G49: The most a GCC learner plausibly pays for this against ELSA at $13.33.
A50: Acquisition floor — lowest price where LTV/CAC >= target | B50: =IFERROR(INDEX(A34:A46,MATCH(TRUE(),INDEX(F34:F46>=$B$30,0),0)),"none on this grid") -> none on this grid | C50: USD/mo | G50: Below this, a subscriber never repays what it cost to acquire them. If this reads 'none', no price on the grid clears the threshold.
A51: Is there a viable price band? | B51: =IF(ISNUMBER(B50),IF(B50<=B49,"YES — price between the floor and the ceiling","NO — floor exceeds ceiling"),"NO — no price clears LTV/CAC at this conversion and CAC") -> NO — no price clears LTV/CAC at this conversion and CAC | G51: This is the sheet's real output.
...

Sheet Cost to Serve
A1: Cost to serve — current vs target architecture
A3: The audit found inference costing $21-24 per MAU per year against blended ARPU of $7-9. This sheet shows why, and what ADR-0001 changes. The unit is one scored practice session.
A5: UNIT PRICES (verified, Sep 2026)
A6: Transcription — gpt-4o-transcribe | B6: 0.006 | C6: USD/min | D6: OpenAI pricing page, Sep 2026.
A7: Transcription — gpt-4o-mini-transcribe | B7: 0.003 | C7: USD/min | D7: OpenAI pricing page, Sep 2026.
A8: Frontier LLM input | B8: 2 | C8: USD/1M tok | D8: gpt-5.6-terra short context, OpenAI pricing page, Sep 2026.
A9: Frontier LLM output | B9: 12 | C9: USD/1M tok | D9: gpt-5.6-terra short context.
A10: Small LLM input | B10: 0.2 | C10: USD/1M tok | D10: gpt-5.6-luna short context.
A11: Small LLM output | B11: 1.2 | C11: USD/1M tok | D11: gpt-5.6-luna short context.
A12: GPU node cost | B12: 0.7 | C12: USD/hr | D12: ESTIMATE — validate. L4-class instance, on-demand.
A13: Utterances per GPU-hour (batched) | B13: 8000 | C13: utterances | D13: ESTIMATE — validate by benchmark. wav2vec2-base on a 5s clip is tens of ms on GPU; this derates heavily for I/O and idle.
A15: CURRENT ARCHITECTURE — cost per scored session
A16: Transcription | B16: =B6*(Assumptions!B31/60) -> 0.0005 | C16: USD | D16: Utterance length / 60 x per-minute rate.
A17: Assessment LLM — input tokens | B17: 600 | C17: tokens | D17: Profile, reference text, transcript, system prompt.
A18: Assessment LLM — output tokens | B18: 700 | C18: tokens | D18: Scores, drills, guide, prioritised actions.
A19: Assessment LLM cost | B19: =(B17/1000000*B8)+(B18/1000000*B9) -> 0.0096 | C19: USD
A20: CURRENT — cost per session | B20: =B16+B19 -> 0.0101 | C20: USD
A22: TARGET ARCHITECTURE (ADR-0001) — cost per scored session
A23: Acoustic scoring — self-hosted GOP | B23: =IFERROR(B12/B13,0) -> 8.75e-05 | C23: USD | D23: GPU hourly rate / utterances per hour. Replaces both transcription and LLM assessment.
A24: Coaching text — input tokens | B24: 350 | C24: tokens | D24: Measurements in, not raw audio or long context.
A25: Coaching text — output tokens | B25: 180 | C25: tokens | D25: One or two sentences of feedback.
A26: Coaching text cost | B26: =(B24/1000000*B10)+(B25/1000000*B11) -> 0.000286 | C26: USD | D26: Routed to the small model.
A27: TARGET — cost per session | B27: =B23+B26 -> 0.0003735 | C27: USD
A28: Cost reduction | B28: =IFERROR(B20/B27,0) -> 27.041499 | C28: x
A30: COMPANION / SCENARIO TURN
A31: Turn — input tokens | B31: 1000 | C31: tokens | D31: Conversation history plus scenario context.
A32: Turn — output tokens | B32: 400 | C32: tokens | D32: In-character reply plus scores plus feedback.
A33: Turn cost — frontier model | B33: =(B31/1000000*B8)+(B32/1000000*B9) -> 0.0068 | C33: USD
A34: Turn cost — small model | B34: =(B31/1000000*B10)+(B32/1000000*B11) -> 0.00068 | C34: USD | D34: Routing decision: use the small model below B2 level.
A36: ANNUAL COST PER USER
A37: Free MAU — current architecture | B37: =(Assumptions!B27*B20+Assumptions!B30*B33)*12 -> 2.1072 | C37: USD/yr
A38: Free MAU — target architecture | B38: =(Assumptions!B27*B27+Assumptions!B30*B34)*12 -> 0.119064 | C38: USD/yr
A39: Paid MAU — current architecture | B39: =(Assumptions!B28*B20+Assumptions!B29*B33)*12 -> 8.718 | C39: USD/yr
A40: Paid MAU — target architecture | B40: =(Assumptions!B28*B27+Assumptions!B29*B34)*12 -> 0.52809 | C40: USD/yr
A42: Blended cost per MAU per year (target) | B42: =B38*(1-Assumptions!B20)+B40*Assumptions!B20 -> 0.13102801 | D42: Weighted by the conversion rate. This is the number that must sit below ARPU for the free tier to survive.
A43: Blended cost per MAU per year (current) | B43: =B37*(1-Assumptions!B20)+B39*Assumptions!B20 -> 2.3005659 | D43: The audit's $21-24 figure, rebuilt bottom-up from the same drivers.
A46: CORRECTION — the audited cost figure
A47: Audited portal's implied cost per MAU (2027) | B47: =120000/5000 -> 24 | D47: The audited business case listed $120,000 of API cost against 5,000 MAU. That is $24 per MAU per year.
A48: Audited portal's implied cost per MAU (2028) | B48: =540000/25000 -> 21.6 | D48: $540,000 against 25,000 MAU — $21.60 per MAU per year.
A49: This model's bottom-up figure, same architecture | B49: =B43 -> 2.3005659 | D49: Built from published unit prices and explicit usage assumptions.
...

Sheet Model A Metered Freemium
A1: Model A — Metered Freemium (consumer, GCC-first)
A3: Free tier metered at 5 scored recordings per week — enough to build a habit, not enough to be the product. Premium at the price the elasticity curve and the affordability ceiling agree on, PPP-adjusted by store region. This is the model the audit's cost finding was about: it only works because ADR-0001 takes blended cost per MAU below ARPU. Run it against the CURRENT architecture row to see why it did not work before.
A6: Line | B6: Year 1 | C6: Year 2 | D6: Year 3 | E6: Note
A7: MAU (exit) | B7: =Assumptions!B15 -> 2500 | C7: =Assumptions!B16 -> 15000 | D7: =Assumptions!B17 -> 55000 | E7: Planning inputs on the Assumptions sheet.
A8: Average MAU over the year | B8: =B7/2 -> 1250 | C8: =(B7+C7)/2 -> 8750 | D8: =(C7+D7)/2 -> 35000 | E8: Costs accrue on average MAU, not exit MAU. The old model used exit and overstated nothing here but hid the shape.
A9: Paid subscribers (exit) | B9: =B7*Assumptions!$B$20 -> 73.125 | C9: =C7*Assumptions!$B$20 -> 438.75 | D9: =D7*Assumptions!$B$20 -> 1608.75 | E9: MAU x blended conversion. THIS is the step the audited model skipped.
A10: Realised ARPU per paid sub, per year | B10: ='Price Elasticity'!$B$53*12*'Price Elasticity'!$C$22*(1-Assumptions!$B$21*Assumptions!$B$22)*(1-Assumptions!$B$39) -> 57.694648 | C10: ='Price Elasticity'!$B$53*12*'Price Elasticity'!$C$22*(1-Assumptions!$B$21*Assumptions!$B$22)*(1-Assumptions!$B$39) -> 57.694648 | D10: ='Price Elasticity'!$B$53*12*'Price Elasticity'!$C$22*(1-Assumptions!$B$21*Assumptions!$B$22)*(1-Assumptions!$B$39) -> 57.694648 | E10: Headline price x 12, x blended PPP multiplier, less the annual-plan discount on the annual share, less store/payment fees.
A11: REVENUE | B11: =B9*B10 -> 4218.9211 | C11: =C9*C10 -> 25313.527 | D11: =D9*D10 -> 92816.264
A13: COST
A14: Inference — target architecture | B14: =B8*'Cost to Serve'!$B$42 -> 163.78501 | C14: =C8*'Cost to Serve'!$B$42 -> 1146.4951 | D14: =D8*'Cost to Serve'!$B$42 -> 4585.9804 | E14: Average MAU x blended cost per MAU. Paid on every active, converted or not.
A15: Inference — if built on the OLD architecture | B15: =B8*'Cost to Serve'!$B$43 -> 2875.7074 | C15: =C8*'Cost to Serve'!$B$43 -> 20129.952 | D15: =D8*'Cost to Serve'!$B$43 -> 80519.807 | E15: Shown for contrast. This row is why the audited model showed negative gross profit in every year.
A16: Hosting + GPU node | B16: =(Assumptions!$B$40+Assumptions!$B$41)*12 -> 7680 | C16: =(Assumptions!$B$40+Assumptions!$B$41)*12 -> 7680 | D16: =(Assumptions!$B$40+Assumptions!$B$41)*12 -> 7680 | E16: Fixed infrastructure. The GPU node is what buys the cost reduction above.
A17: Acquisition | B17: =B7*Assumptions!$B$42 -> 30000 | C17: =(C7-B7)*Assumptions!$B$42 -> 150000 | D17: =(D7-C7)*Assumptions!$B$42 -> 480000 | E17: CAC on net new MAU. Assumes organic dominates; paid acquisition in MENA runs well above this.
A18: People | B18: =Assumptions!$B$43*12 -> 0 | C18: =Assumptions!$B$43*12 -> 0 | D18: =Assumptions!$B$43*12 -> 0 | E18: Zero while founder-led. Put a real number here before showing anyone a margin.
A19: TOTAL COST | B19: =SUM(B14:B14)+B16+B17+B18 -> 37843.785 | C19: =C14+C16+C17+C18 -> 158826.5 | D19: =D14+D16+D17+D18 -> 492265.98
A21: GROSS PROFIT (rev less inference) | B21: =B11-B14 -> 4055.1361 | C21: =C11-C14 -> 24167.032 | D21: =D11-D14 -> 88230.284
A22: Gross margin | B22: =IFERROR(B21/B11,0) -> 0.96117846 | C22: =IFERROR(C21/C11,0) -> 0.9547082 | D22: =IFERROR(D21/D11,0) -> 0.95059077
A23: EBITDA | B23: =B11-B19 -> -33624.864 | C23: =C11-C19 -> -133512.97 | D23: =D11-D19 -> -399449.72
A25: UNIT ECONOMICS
A26: LTV per paid sub | B26: =B10/12*Assumptions!$B$24 -> 87.416133 | C26: =B10/12*Assumptions!$B$24 -> 87.416133 | D26: =B10/12*Assumptions!$B$24 -> 87.416133 | E26: Monthly realised ARPU x average lifetime from churn.
A27: CAC per paid sub | B27: =IFERROR(Assumptions!$B$42/Assumptions!$B$20,0) -> 410.25641 | C27: =IFERROR(Assumptions!$B$42/Assumptions!$B$20,0) -> 410.25641 | D27: =IFERROR(Assumptions!$B$42/Assumptions!$B$20,0) -> 410.25641 | E27: Blended CAC grossed up by conversion — you pay to acquire the free users too.
A28: LTV / CAC | B28: =IFERROR(B26/B27,0) -> 0.21307682 | C28: =IFERROR(B26/B27,0) -> 0.21307682 | D28: =IFERROR(B26/B27,0) -> 0.21307682 | E28: Below 3.0x this model does not fund its own growth.
A29: Contribution per MAU per year | B29: =IFERROR(B21/B8,0) -> 3.2441089 | C29: =IFERROR(C21/C8,0) -> 2.7619465 | D29: =IFERROR(D21/D8,0) -> 2.5208653 | E29: The single number that decides whether a free tier is an asset or a liability.

Sheet Model B Institutional
A1: Model B — Institutional licensing (B2B2C)
A3: Per-seat licensing to universities, employers and relocation programmes in the GCC. No free tier, so every served user is a paid user and the free-rider cost problem disappears by construction. The trade is a sales cycle measured in quarters and a product surface — admin, cohorts, reporting, SSO — that does not exist yet.
A6: Line | B6: Year 1 | C6: Year 2 | D6: Year 3 | E6: Note
A7: Accounts closed (cumulative) | B7: 3 | C7: 12 | D7: 34 | E7: ESTIMATE — validate. Founder-led sales. Assumes one pilot converts per quarter in Y1.
A8: Average seats per account | B8: 120 | C8: 180 | D8: 240 | E8: ESTIMATE — validate. A university department or a mid-size employer cohort.
A9: Total seats | B9: =B7*B8 -> 360 | C9: =C7*C8 -> 2160 | D9: =D7*D8 -> 8160
A10: Price per seat per year | B10: 36 | C10: 36 | D10: 42 | E10: KEY LEVER. Below the $18.20/user/month ELSA charges its Team tier, because Slang sells depth in one language pair rather than breadth.
A11: Seat utilisation (active / licensed) | B11: 0.55 | C11: 0.6 | D11: 0.65 | E11: Institutional seats are bought in bulk and used in part. Revenue is on seats; cost is on active users.
A12: REVENUE | B12: =B9*B10 -> 12960 | C12: =C9*C10 -> 77760 | D12: =D9*D10 -> 342720
A14: COST
A15: Inference (active seats only) | B15: =B9*B11*'Cost to Serve'!$B$40 -> 104.56182 | C15: =C9*C11*'Cost to Serve'!$B$40 -> 684.40464 | D15: =D9*D11*'Cost to Serve'!$B$40 -> 2800.9894 | E15: Paid-intensity cost, but only on the seats actually used. Under-utilisation is margin here, not waste.
A16: Hosting + GPU node | B16: =(Assumptions!$B$40+Assumptions!$B$41)*12 -> 7680 | C16: =(Assumptions!$B$40+Assumptions!$B$41)*12 -> 7680 | D16: =(Assumptions!$B$40+Assumptions!$B$41)*12 -> 7680
A17: Sales + account management | B17: 9000 | C17: 42000 | D17: 96000 | E17: ESTIMATE — validate. Founder-led in Y1; one AE from Y2. This is the cost the consumer model does not carry.
A18: Admin / reporting product build | B18: 24000 | C18: 12000 | D18: 12000 | E18: ESTIMATE — validate. Contractor build of the admin surface: cohorts, seat management, SSO, exports.
A19: TOTAL COST | B19: =B15+B16+B17+B18 -> 40784.562 | C19: =C15+C16+C17+C18 -> 62364.405 | D19: =D15+D16+D17+D18 -> 118480.99
A21: GROSS PROFIT (rev less inference) | B21: =B12-B15 -> 12855.438 | C21: =C12-C15 -> 77075.595 | D21: =D12-D15 -> 339919.01
A22: Gross margin | B22: =IFERROR(B21/B12,0) -> 0.99193196 | C22: =IFERROR(C21/C12,0) -> 0.9911985 | D22: =IFERROR(D21/D12,0) -> 0.99182718
A23: EBITDA | B23: =B12-B19 -> -27824.562 | C23: =C12-C19 -> 15395.595 | D23: =D12-D19 -> 224239.01
A25: UNIT ECONOMICS
A26: ACV per account | B26: =IFERROR(B12/B7,0) -> 4320 | C26: =IFERROR(C12/C7,0) -> 6480 | D26: =IFERROR(D12/D7,0) -> 10080
A27: Contribution per active seat | B27: =IFERROR(B21/(B9*B11),0) -> 64.926455 | C27: =IFERROR(C21/(C9*C11),0) -> 59.47191 | D27: =IFERROR(D21/(D9*D11),0) -> 64.087295

Sheet Model C Assessment
A1: Model C — Assessment-led (practice free, certification paid)
A3: Practice is free and metered. Revenue comes from assessment events: a structured placement and progress report priced per sitting. This is the model that aligns price with the thing the acoustic engine is uniquely good at, and the only one where the moat is what the customer is literally paying for. It is also the model with the weakest evidence — nobody has shown MENA consumers will pay per assessment for a non-accredited report.
A6: Line | B6: Year 1 | C6: Year 2 | D6: Year 3 | E6: Note
A7: MAU (exit) | B7: =Assumptions!B15 -> 2500 | C7: =Assumptions!B16 -> 15000 | D7: =Assumptions!B17 -> 55000
A8: Average MAU | B8: =B7/2 -> 1250 | C8: =(B7+C7)/2 -> 8750 | D8: =(C7+D7)/2 -> 35000
A9: Assessment attach rate | B9: 0.08 | C9: 0.12 | D9: 0.15 | E9: KEY LEVER, and the weakest evidence in the workbook. Share of MAU who buy at least one assessment per year.
A10: Assessments per buyer per year | B10: 2.2 | C10: 2.6 | D10: 3 | E10: ESTIMATE — validate. Placement plus progress re-tests.
A11: Price per assessment (GCC) | B11: 19 | C11: 19 | D11: 22 | E11: KEY LEVER. Priced as an event, not a subscription. PPP-adjusted for Tier 3 markets.
A12: REVENUE | B12: =B8*B9*B10*B11*'Price Elasticity'!$C$22*(1-Assumptions!$B$39) -> 2646.985 | C12: =C8*C9*C10*C11*'Price Elasticity'!$C$22*(1-Assumptions!$B$39) -> 32846.677 | D12: =D8*D9*D10*D11*'Price Elasticity'!$C$22*(1-Assumptions!$B$39) -> 219421.12
A14: COST
A15: Inference — free practice on all MAU | B15: =B8*'Cost to Serve'!$B$38 -> 148.83 | C15: =C8*'Cost to Serve'!$B$38 -> 1041.81 | D15: =D8*'Cost to Serve'!$B$38 -> 4167.24 | E15: Every active user costs, whether or not they ever buy an assessment. Highest free-rider exposure of the three models.
A16: Hosting + GPU node | B16: =(Assumptions!$B$40+Assumptions!$B$41)*12 -> 7680 | C16: =(Assumptions!$B$40+Assumptions!$B$41)*12 -> 7680 | D16: =(Assumptions!$B$40+Assumptions!$B$41)*12 -> 7680
A17: Acquisition | B17: =B7*Assumptions!$B$42 -> 30000 | C17: =(C7-B7)*Assumptions!$B$42 -> 150000 | D17: =(D7-C7)*Assumptions!$B$42 -> 480000
A18: Rater panel / calibration upkeep | B18: 6000 | C18: 14000 | D18: 22000 | E18: ESTIMATE — validate. Human raters maintaining score validity. Non-negotiable if you sell a score.
A19: TOTAL COST | B19: =B15+B16+B17+B18 -> 43828.83 | C19: =C15+C16+C17+C18 -> 172721.81 | D19: =D15+D16+D17+D18 -> 513847.24
A21: GROSS PROFIT (rev less inference) | B21: =B12-B15 -> 2498.155 | C21: =C12-C15 -> 31804.868 | D21: =D12-D15 -> 215253.89
A22: Gross margin | B22: =IFERROR(B21/B12,0) -> 0.94377377 | C22: =IFERROR(C21/C12,0) -> 0.96828264 | D22: =IFERROR(D21/D12,0) -> 0.98100803
A23: EBITDA | B23: =B12-B19 -> -41181.845 | C23: =C12-C19 -> -139875.13 | D23: =D12-D19 -> -294426.11

Sheet Comparison
A1: Model comparison and recommendation
A3: Metric | B3: A — Metered Freemium | C3: B — Institutional | D3: C — Assessment-led | E3: Read
A4: Year 3 revenue | B4: ='Model A Metered Freemium'!D11 -> 92816.264 | C4: ='Model B Institutional'!D12 -> 342720 | D4: ='Model C Assessment'!D12 -> 219421.12 | E4: Absolute scale.
A5: Year 3 gross profit | B5: ='Model A Metered Freemium'!D21 -> 88230.284 | C5: ='Model B Institutional'!D21 -> 339919.01 | D5: ='Model C Assessment'!D21 -> 215253.89 | E5: Revenue less inference.
A6: Year 3 gross margin | B6: ='Model A Metered Freemium'!D22 -> 0.95059077 | C6: ='Model B Institutional'!D22 -> 0.99182718 | D6: ='Model C Assessment'!D22 -> 0.98100803 | E6: B is structurally highest — no free riders.
A7: Year 3 EBITDA | B7: ='Model A Metered Freemium'!D23 -> -399449.72 | C7: ='Model B Institutional'!D23 -> 224239.01 | D7: ='Model C Assessment'!D23 -> -294426.11 | E7: After all modelled cost.
A8: Year 1 EBITDA | B8: ='Model A Metered Freemium'!B23 -> -33624.864 | C8: ='Model B Institutional'!B23 -> -27824.562 | D8: ='Model C Assessment'!B23 -> -41181.845 | E8: How deep the hole is before it turns.
A10: QUALITATIVE SCORING (1 = weak, 5 = strong)
A11: Criterion | B11: A | C11: B | D11: C | E11: Why
A12: Speed to first revenue | B12: 5 | C12: 2 | D12: 4 | E12: A ships behind a paywall flag this month. B needs an admin product and a sales cycle.
A13: Defensibility of the moat | B13: 3 | C13: 4 | D13: 5 | E13: C sells the acoustic engine directly. A sells a habit anyone can copy.
A14: Margin structure | B14: 3 | C14: 5 | D14: 3 | E14: B pays inference only on licensed seats. A and C both carry free riders.
A15: Evidence it will work | B15: 4 | C15: 3 | D15: 2 | E15: A is the proven consumer pattern. C has no MENA precedent for paid non-accredited assessment.
A16: Founder fit (solo, no sales team) | B16: 5 | C16: 2 | D16: 4 | E16: B needs enterprise selling and procurement patience.
A17: Data flywheel strength | B17: 4 | C17: 5 | D17: 3 | E17: B produces dense labelled cohorts — the fastest route to the confusion map.
A18: Capital required before revenue | B18: 5 | C18: 2 | D18: 3 | E18: B needs the admin build funded up front.
A19: TOTAL | B19: =SUM(B12:B18) -> 29 | C19: =SUM(C12:C18) -> 23 | D19: =SUM(D12:D18) -> 24
A21: RECOMMENDATION
A22: Sequence, not choose. | B22: A now, B from month 9, C only once calibration data exists. These are not three alternatives; they are three phases with different evidence requirements.
A23: Phase 1 — Model A (months 0-9). | B23: Metered freemium at the recommended GCC price. It is the only model you can ship alone this quarter, and it is what generates the labelled recordings everything else depends on. Success test: contribution per MAU positive, and 200+ consented recordings in the corpus.
A24: Phase 2 — Model B (months 9-24). | B24: Institutional licensing is where the margin is, and GCC universities and employers are a reachable, concentrated buyer set. Do not start it before Phase 1 proves the pedagogy works, because the first enterprise reference is worth more than the first ten.
A25: Phase 3 — Model C (month 18+). | B25: Only after ADR-0002 calibration produces a defensible correlation against human raters. Selling a score you have not validated is the finding that ended the last version of this business case.
A26: The kill criterion. | B26: If, after 1,000 MAU, contribution per MAU is still negative under the target architecture, the consumer model does not work at MENA price points and B becomes the primary, not the sequel. Check this quarterly against the Model A contribution row.
A27: What decides it. | B27: Not the revenue column. The three models differ far more in evidence risk than in modelled revenue, and every revenue number here rests on a yellow cell. Treat the ranking as a sequencing argument, not a forecast.
A29: RECONCILIATION — the scorecard and the P&L disagree. The P&L wins.
A30: The qualitative scorecard above ranks A highest (29 vs 24 vs 23) on speed, founder fit and capital need. The modelled P&L says A is the only one of the three that never reaches profitability, and B is the only one that does. Both are correct, and the contradiction is the finding: A scores well on everything except the one thing that decides it. At the assumed blended CAC of $12, Model A spends $410 to acquire a subscriber worth $87 — LTV/CAC of 0.21x. No price on the grid fixes that, because raising price costs more conversion than it gains in rate. Model A is a DISTRIBUTION problem wearing a pricing problem's clothes.
A35: MODEL A UNDER ORGANIC ACQUISITION
A36: Line | B36: At assumed CAC ($12) | C36: At max allowable CAC | D36: Delta | E36: Read
A37: Max CAC that clears 3x LTV/CAC | C37: ='Price Elasticity'!B57 -> 0.85230729 | E37: From 'Price Elasticity' → What binds. The ceiling on blended acquisition cost.
A38: Year 3 acquisition spend | B38: ='Model A Metered Freemium'!D17 -> 480000 | C38: =(Assumptions!B17-Assumptions!B16)*'Price Elasticity'!B57 -> 34092.292 | D38: =C38-B38 -> -445907.71 | E38: Same 40,000 net-new users, two different costs per user.
A39: Year 3 EBITDA | B39: ='Model A Metered Freemium'!D23 -> -399449.72 | C39: ='Model A Metered Freemium'!D11-'Model A Metered Freemium'!D14-'Model A Metered Freemium'!D16-((Assumptions!B17-Assumptions!B16)*'Price Elasticity'!B57)-'Model A Metered Freemium'!D18 -> 46457.992 | D39: =C39-B39 -> 445907.71 | E39: The whole consumer thesis turns on this line. Organic acquisition flips Model A profitable; any paid channel does not.
A41: THE DECISION
A42: Model B is the commercial engine. | B42: It is the only model that reaches positive EBITDA inside three years at these assumptions, and it does so in Year 2. Institutional selling converts an entire cohort on a single sale, which is precisely the constraint that defeats Model A. Build the admin surface.
A43: Model A is the wedge — with a hard rule attached. | B43: Ship it, price it at the education median, and give it a ZERO paid-acquisition budget. Community, campus societies, employer HR channels, content and referral only. The moment a paid channel is switched on, the model stops working and the spreadsheet says so.
A44: Model C waits for evidence. | B44: Selling an assessment score before ADR-0002 calibration exists is the same class of error the 12 Sep audit found: a number presented as measurement without a validation study behind it. Revisit at month 18.
A45: The number to watch monthly. | B45: Blended CAC against the max allowable on 'Price Elasticity' B57. It is the single kill criterion for the consumer model, and it is checkable from day one.
A46: What would change this. | B46: A conversion rate materially above 2.9%, or a CAC materially below $1. Both are yellow cells. Validate conversion first: it moves the answer more than price does, and it is cheaper to measure.

Sheet Sensitivity
A1: Sensitivity — what breaks Model A, and at what value
A3: Each row moves one driver and leaves everything else alone. The point is not the numbers; it is which drivers the answer is actually sensitive to, so you know which yellow cells to go and validate first.
A6: Driver | B6: Downside | C6: Base | D6: Upside
A7: Price elasticity (e) | B7: 2 | C7: ='Price Elasticity'!B27 -> 1.4 | D7: 1
A8: Blended MAU-to-paid conversion | B8: 0.015 | C8: =Assumptions!B20 -> 0.02925 | D8: 0.045
A9: Monthly churn | B9: 0.08 | C9: =Assumptions!B23 -> 0.055 | D9: 0.035
A10: Blended CAC | B10: 25 | C10: =Assumptions!B42 -> 12 | D10: 6
A11: GCC share of base | B11: 0.25 | C11: =Assumptions!B34 -> 0.45 | D11: 0.65
A12: Utterances per GPU-hour | B12: 3000 | C12: ='Cost to Serve'!B13 -> 8000 | D12: 15000
A13: Free-user sessions per month | B13: 25 | C13: =Assumptions!B27 -> 12 | D13: 6
A15: HOW TO USE THIS
A16: 1. Copy the workbook. In the copy, paste one downside value into the driver's home cell on Assumptions or Price Elasticity.
A17: 2. Read 'Model A Metered Freemium' → Contribution per MAU per year, and → EBITDA Year 3.
A18: 3. Record which single driver flips contribution negative on its own. That driver is your first validation spend.
A19: 4. Repeat for the upside column to see which driver is worth optimising rather than merely defending.
A21: Expected result before you run it: elasticity and free-user session volume dominate, because both act on every
A22: monthly active rather than only on the converted minority. Conversion and CAC matter less than they feel like they should.
A23: If your run disagrees with that, the model has a bug — investigate before you trust the output.

Sheet Sources
A1: Sources — every external number in this workbook
A3: A number that is not in this table is an ESTIMATE and is marked yellow in the model. That distinction is the whole point: the audited version of this business case failed because estimates and facts were rendered identically.
A6: Figure | B6: Value | C6: Where used | D6: Source
A7: Digital English learning market, 2026 | B7: $15.98bn → $31.62bn by 2031, 14.62% CAGR | C7: Assumptions B5 | D7: Mordor Intelligence — Digital English Language Learning Market
A8: Middle East e-learning market | B8: $16.17bn (2025) → $28.28bn (2034), 6.41% CAGR | C8: Assumptions B6 | D8: IMARC Group — Middle East E-Learning Market
A9: Duolingo Super pricing | B9: $16.99/mo · $119.99/yr · Lite $35.99/yr · Family $143.99/yr | C9: Price Elasticity row 8 | D9: languageappguide.com, Sep 2026
A10: ELSA Speak pricing | B10: $21.99/mo · $159.99/yr ($13.33/mo effective) · Team $18.20/user/mo · free tier exists | C10: Price Elasticity row 9 | D10: softwarefinder.com/lms/elsa-speak/pricing, 2026
A11: Education category median price | B11: $9.99/month | C11: Price Elasticity row 10 (anchor) | D11: RevenueCat — State of Subscription Apps 2026, Education
A12: Education D30 download-to-trial | B12: 6.5% median | C12: Assumptions B18 | D12: RevenueCat — State of Subscription Apps 2026, Education
A13: Education annual-plan preference | B13: 59-66% of categories favouring annual | C13: Assumptions B21 | D13: RevenueCat — State of Subscription Apps 2026
A14: PPP price tiers | B14: GCC 1.00 · Jordan 0.70 · Egypt/Morocco 0.50 · India 0.35 | C14: Price Elasticity rows 15-17 | D14: pricepush.app — App Price Localization Cheat Sheet (World Bank PPP + A/B overlay)
A15: Transcription unit price | B15: gpt-4o-transcribe $0.006/min · gpt-4o-mini-transcribe $0.003/min | C15: Cost to Serve B6, B7 | D15: OpenAI pricing page, Sep 2026
A16: Frontier LLM unit price | B16: gpt-5.6-terra $2.00 in / $12.00 out per 1M tokens | C16: Cost to Serve B8, B9 | D16: OpenAI pricing page, Sep 2026
A17: Small LLM unit price | B17: gpt-5.6-luna $0.20 in / $1.20 out per 1M tokens | C17: Cost to Serve B10, B11 | D17: OpenAI pricing page, Sep 2026
... A20: Benchmark corpus gap | B20: speechocean762 = 5,000 utterances, 250 Mandarin-L1 speakers. No Arabic-L1 equivalent exists. | C20: Moat thesis | D20: Zhang et al., Interspeech 2021; openslr.org/101
